# Ch.14 Error Handling in Practice

## A. 에러 관리
커스텀 에러, 상황에 따른 에러 검출 주의

### 1. 가장 흔하게 발생하는 에러

+ 인터넷 연결 없음: 아주 흔한 에러 중 하나다. 만약 앱이 인터넷 연결을 통해 데이터를 받아와야하는데 기기가 오프라인 상태가 된다면, 이를 감지하고 적절한 대응을 해줘야 한다.
+ 잘못된 입력: 때에 따라서 정해진 폼에 따라서 입력값이 필요한 경우가 있다. 하지만 사용자는 언제든지 잘못된 값을 입력할 수 있다. 전화번호 입력란에 숫자대신 글자를 입력하는 사용자는 언제나 있을 수 있다. 항상 타입에 유의하자
+ API 또는 HTTP 에러: API를 통한 에러는 아주 광범위하게 일어난다. 표준 HTTP 에러(400 또는 500 에러)를 통해 표시되거나 JSON 내 status 필드를 통해 표시될 수 있다.

### 2. RxSwift에서의 에러관리

+ Catch: 기본값defaultValue으로 error 복구하기
<img src = "https://github.com/fimuxd/RxSwift/raw/master/Lectures/14_Error%20Handling%20in%20Practice/1.catch.png?raw=true" width = "400">

+ Retry: 제한적 또는 무제한으로 재시도Retry 하기
<img src = "https://github.com/fimuxd/RxSwift/raw/master/Lectures/14_Error%20Handling%20in%20Practice/2.retry.png?raw=true" width = "400">

### 3. 에러 throw
Apple의 프레임워크에 기반의 시스템 에러(NSError)를 래핑한 RxCocoa의 에러 관리
RxCocoa/URLSession+Rx.swift 내부 데이터 요청 메서드를 예를 들면 NSURLRequest를 받아 Data 타입의 Observable을 반환한다.

```swift
public func data(request: URLRequest) -> Ovservable<Data> { ... }

...

 if 200 ..< 300 ~= pair.0.statusCode {
 	return pair.1
 }
 else {
     // 에러 부분에 대해선 return이 없다.
     // flatMap 연산자를 사용하여 해당 데이터를 받아올 때, 발생한 에러를 내보내고 싶다면 throw를 활용하여 에러를 처리해야한다.

 	throw RxCocoaURLError.httpRequestFailed(response: pair.0, data: pair.1)
 }

 ...

```

## B. catch를 사용한 에러 관리

위에서 데이터 패칭 시 에러가 있는 경우 throw로 던지는 것에 대해서 알아보았다. 그렇다면, 이런 던져진 에러를 처리는 방식으로 가장 기본적인 catch를 생각해보자. catch 연산자는 기본 Swift에서 do-try-catch 구문을 통해 쓰였던 것과 비슷하다. observable이 실행되고 혹시 거기서 잘못된 점이 있으면 에러를 감싼 이벤트가 반환된다.

일반적으로 생각해보면 Observable 이벤트의 경우 onError, onCompleted의 경우처럼 구독으로 해당 에러가 전달되게 된다면 이로 인해 모든 구독이 dispose 된다.observable은 반드시 완전종료되고 에러 다음의 이벤트는 모두 무시되는 것이다.

### 1. catchError(_ handler:)

```swift
 func catchError(_ handler:) -> RxSwift.Observable<Self.E>
```

 클로저를 매개변수로 받아서 완전히 다른 형태의 observable로 반환한다. 해당 옵션은 주로 observable 에러가 발생하면 이전의 에러가 발생되지 않은 정상적인 값이 keyValue로 캐싱되어 있다면 해당 값을 반환하는 방식으로 사용이 된다.

 <img src =  "https://github.com/fimuxd/RxSwift/raw/master/Lectures/14_Error%20Handling%20in%20Practice/3.catchError.png?raw=true" width="400">

 ### 2. catchErrorJustReturn(_ element:)

```swift
  func catchErrorJustReturn(_ element:) -> RxSwift.Observable<Self.E>
```

에러를 무시하고 이전에 선언해둔 값을 반환한다. catchError에 비해 제한적이다. 왜냐하면 catchErrorJustReturn은 주어진 유형의 에러에 대한 값을 반환할 수 없기 때문이다. 에러가 무엇이든 관계없이 모든 에러에 대해 동일한 값이 반환된다.

## C. 에러 잡아내기 실습

텍스트 필드에 검색하고자 하는 도시 이름을 입력하면서 do(onNext:) 메서드를 활용하여 캐싱하고자하는 딕셔너리에 값을 저장해두고, 에러가 있을 시에는 .catchErrorJustReturn() 메서드를 통해 미리 선언해두었던 default(empty) 구조체를 반환하거나 .catchError() 메서드를 통해 커스텀 에러를 구분하여 처리할 수 있었다.

## D. retry를 통한 에러 관리

retry 연산자가 observable 에러에서 사용될 때, observable은 스스로를 계속 반복한다. 즉, retry는 observable 내의 전체 작업을 반복한다. 에러를 검출하는 catc류 연산자와는 차이가 있다.

에러 발생시 사용자가 직접 (부적절한 타이밍에) 재시도 함으로써 사용자 인터페이스가 변경되는 부작용을 막기 위해 권장되는 방법으로 에러를 던지기 전에 재시도를 하므로서 사용자의 경험을 증진 시킬 수 있는 방법이다.

### 1. retry(_ maxAttemptCount:)

```swift
 func retry(_ maxAttemptCount:) -> Observable<E>
```

해당 연산자를 통해 몇 번에 걸쳐서 재시도를 할 것인지 지정할 수 있다. 주로 catchError 전에 해당 retry를 수행하면서 일시적인 에러 상황이라면 그에 대한 해소를 할 수 있도록 조치할 수 있다.

### 2. retryWhen(_ notificationHandler:)

```swift
func retryWhen(_ notificationHandler:) -> Observable<E>

...

 .retryWhen{ e in
 	//  flatMap source errors
 	return e.enumerated().flatMap { (attempt, error) -> Observable<Int> in
 		//  attemp few times
 		if attempt >= self.maxAttempts - 1 {
 			return Observable.error(error)
 		}
 	return Observable<Int>.timer(Double(attempt + 1), scheduler: MainScheduler.instance).take(1)
 	}
 }

 ...
```

주된 특징을 에러를 던지는 연산자와 병합하여 사용가능 하도록 구성할 수 있는 것이고 타이머를 활용한 지연 구성 등을 통하여 임의적으로 데이터 패칭 요청을 컨트롤하는 retry를 구성을 하는 것이 가능하다.

## E. 커스텀 에러

### 1. 커스텀 에러 만들어 방출하기

실제로 에러를 구성하면서 enum을 활용하여 Error의 유형을 주로 커스텀한 경험이 있을 거다. status code를 분기하여 해당 에러를 서버와 구상한대로 구성하고 방출하면서 원하는 식으로 UI를 구성하는 듯 side effect를 정의할 수 있다.

```swift
 enum ApiError: Error {
 	case cityNotFound
    case serverFailure
 }

 ...
// 데이터 패칭 부분에서의 status code 기반의 분기 처리
 return session.rx.response(request: request).map() { response, data in
 	if 200 ..< 300 ~= response.statusCode {
 		return try JSON(data: data)
 	} else if response.statusCode == 401 {
        throw ApiError.invalidKey
    } else if 400 ..< 500 ~= response.statusCode {
 		throw ApiError.cityNotFound
 	} else {
 		throw ApiError.serverFailure
 	}
 }

 ...
```

### 2. 방출된 에러 사용하기

에러는 보통 retry나 catch 연산자로 처리된다. 하지만 부수작용을 발생시키고 싶거나 사용자 인터페이스에서 메시지를 띄우고 싶다면 do 연산자를 사용할 수 있었다. retryWhen을 사용할 때도 마찬가지로 do를 사용할 수 있다.

```swift
.do(onNext: { [weak self] data in
        self?.cache[text] = data
    }, onError: { [weak self] error in
        guard let self = self else { return }
        DispatchQueue.main.async {
            self.showError(error: error)
        }
    }
)

...

func showError(error e: Error) {
 	if let e = e as? ApiController.ApiError {
 		switch (e) {
 		case .cityNotFound:
 			InfoView.showIn(viewController: self, message: "City Name is invalid")
 		case .serverFailure:
 			InfoView.showIn(viewController: self, message: "Server error")
        case .invalidKey:
 	        InfoView.showIn(viewController: self, message: "Key is invalid")
 		}
 	} else {
 		InfoView.showIn(viewController: self, message: "An error occurred")
 	}
}
```

## F. 고급 에러 처리

위에서 배운 것을 바탕으로 특정한 상황에 대하여 에러 처리를 더 구체화할 수 있다. 앱에서 만약 인증기능 기반으로 해당 Api key를 활용하고 만료가 되면 갱신하는 상황을 예상해보자

날씨 정보를 요청하기 위해 인증을 거쳐야 한다. 아마 Token을 통해서 사용자가 제대로 로그인 했는지 확인할 세션이 생성될 것이다. 세션이 만료되었다면 어떻게 해야할까? 에러를 반환하거나 빈 값을 반환해야할까?

실질적으로 로그인 화면으로 다시 이동을 하여 갱신 처리를 하거나 이를 재구성하기 위한 경고와 같은 부수적인 처리를 할 수도 있을 것이다.

현재 튜토리얼에서는 앞서 배웠던 retryWhen을 활용하여 재시도를 구성하고 최대 요청횟수와 에러 유형에 따른 분기 처리, 그리고 타이머 처리를 통하여 데이터 패칭 요청을 컨트롤하는 클로저를 구성하는 것을 알 수 있었다.

```swift
let retryHandler: (Observable<Error>) -> Observable<Int> = { e in
  	return e.enumerated().flatMap { (attempt, error) -> Observable<Int> in
  		if attempt >= maxAttempts - 1 {
  			return Observable.error(error)
  		} else if let casted = error as? ApiController.ApiError, casted == .invalidKey {
  			return ApiController.shared.apiKey
  				.filter { $0 != "" }
  				.map { _ in return 1 }
  		}
  		print("== retrying after \(attempt + 1) seconds ==")
  		return Observable<Int>.timer(Double(attempt + 1), scheduler: MainScheduler.instance)
  			.take(1)
  	}
}
```




















